<sdf version='1.11'>
  <model name='robot_presatation'>
    <link name='base_footprint'>
      <inertial>
        <pose>0.0072992700729927031 0 0.10618248175182481 0 0 0</pose>
        <mass>1.3700000000000001</mass>
        <inertia>
          <ixx>0.0075142943795620384</ixx>
          <ixy>0</ixy>
          <ixz>-0.00064817518248175146</ixz>
          <iyy>0.0090013016788321135</iyy>
          <iyz>0</iyz>
          <izz>0.006687747299270074</izz>
        </inertia>
      </inertial>
      <collision name='base_footprint_fixed_joint_lump__base_link_collision'>
        <pose>0 0 0.090999999999999998 0 0 0</pose>
        <geometry>
          <cylinder>
            <length>0.12</length>
            <radius>0.10000000000000001</radius>
          </cylinder>
        </geometry>
      </collision>
      <collision name='base_footprint_fixed_joint_lump__back_caster_link_collision_1'>
        <pose>-0.080000000000000002 0 0.014999999999999999 0 0 0</pose>
        <geometry>
          <sphere>
            <radius>0.016</radius>
          </sphere>
        </geometry>
        <surface>
          <contact>
            <ode>
              <kp>1000000000</kp>
              <kd>1</kd>
            </ode>
          </contact>
          <friction>
            <ode>
              <mu>0</mu>
              <mu2>0</mu2>
            </ode>
          </friction>
        </surface>
      </collision>
      <collision name='base_footprint_fixed_joint_lump__camera_link_collision_2'>
        <pose>0.10000000000000001 0 0.17100000000000001 0 0 0</pose>
        <geometry>
          <box>
            <size>0.02 0.10000000000000001 0.02</size>
          </box>
        </geometry>
        <surface>
          <contact>
            <ode/>
          </contact>
          <friction>
            <ode/>
          </friction>
        </surface>
      </collision>
      <collision name='base_footprint_fixed_joint_lump__front_caster_link_collision_3'>
        <pose>0.080000000000000002 0 0.014999999999999999 0 0 0</pose>
        <geometry>
          <sphere>
            <radius>0.016</radius>
          </sphere>
        </geometry>
        <surface>
          <contact>
            <ode>
              <kp>1000000000</kp>
              <kd>1</kd>
            </ode>
          </contact>
          <friction>
            <ode>
              <mu>0</mu>
              <mu2>0</mu2>
            </ode>
          </friction>
        </surface>
      </collision>
      <collision name='base_footprint_fixed_joint_lump__imu_link_collision_4'>
        <pose>0 0 0.111 0 0 0</pose>
        <geometry>
          <box>
            <size>0.02 0.02 0.02</size>
          </box>
        </geometry>
        <surface>
          <contact>
            <ode/>
          </contact>
          <friction>
            <ode/>
          </friction>
        </surface>
      </collision>
      <collision name='base_footprint_fixed_joint_lump__laser_cylinder_link_collision_5'>
        <pose>0 0 0.191 0 0 0</pose>
        <geometry>
          <cylinder>
            <length>0.10000000000000001</length>
            <radius>0.01</radius>
          </cylinder>
        </geometry>
        <surface>
          <contact>
            <ode/>
          </contact>
          <friction>
            <ode/>
          </friction>
        </surface>
      </collision>
      <collision name='base_footprint_fixed_joint_lump__laser_link_collision_6'>
        <pose>0 0 0.24099999999999999 0 0 0</pose>
        <geometry>
          <cylinder>
            <length>0.02</length>
            <radius>0.02</radius>
          </cylinder>
        </geometry>
        <surface>
          <contact>
            <ode/>
          </contact>
          <friction>
            <ode/>
          </friction>
        </surface>
      </collision>
      <visual name='base_footprint_fixed_joint_lump__base_link_visual'>
        <pose>0 0 0.090999999999999998 0 0 0</pose>
        <geometry>
          <cylinder>
            <length>0.12</length>
            <radius>0.10000000000000001</radius>
          </cylinder>
        </geometry>
        <material>
          <diffuse>1 1 1 0.5</diffuse>
          <ambient>1 1 1 0.5</ambient>
        </material>
      </visual>
      <visual name='base_footprint_fixed_joint_lump__back_caster_link_visual_1'>
        <pose>-0.080000000000000002 0 0.014999999999999999 0 0 0</pose>
        <geometry>
          <sphere>
            <radius>0.016</radius>
          </sphere>
        </geometry>
        <material>
          <diffuse>1 0 0 0.800000012</diffuse>
          <ambient>1 0 0 0.800000012</ambient>
        </material>
      </visual>
      <visual name='base_footprint_fixed_joint_lump__camera_link_visual_2'>
        <pose>0.10000000000000001 0 0.17100000000000001 0 0 0</pose>
        <geometry>
          <box>
            <size>0.02 0.10000000000000001 0.02</size>
          </box>
        </geometry>
        <material>
          <script>
            <name>Gazebo/Black</name>
            <uri>file://media/materials/scripts/gazebo.material</uri>
          </script>
          <diffuse>0 0 0 0.5</diffuse>
          <ambient>0 0 0 0.5</ambient>
        </material>
      </visual>
      <visual name='base_footprint_fixed_joint_lump__front_caster_link_visual_3'>
        <pose>0.080000000000000002 0 0.014999999999999999 0 0 0</pose>
        <geometry>
          <sphere>
            <radius>0.016</radius>
          </sphere>
        </geometry>
        <material>
          <diffuse>1 0 0 0.800000012</diffuse>
          <ambient>1 0 0 0.800000012</ambient>
        </material>
      </visual>
      <visual name='base_footprint_fixed_joint_lump__imu_link_visual_4'>
        <pose>0 0 0.111 0 0 0</pose>
        <geometry>
          <box>
            <size>0.02 0.02 0.02</size>
          </box>
        </geometry>
        <material>
          <script>
            <name>Gazebo/Grey</name>
            <uri>file://media/materials/scripts/gazebo.material</uri>
          </script>
          <diffuse>0.37500003 0.37500003 0.37500003 1</diffuse>
          <ambient>0.37500003 0.37500003 0.37500003 1</ambient>
        </material>
      </visual>
      <visual name='base_footprint_fixed_joint_lump__laser_cylinder_link_visual_5'>
        <pose>0 0 0.191 0 0 0</pose>
        <geometry>
          <cylinder>
            <length>0.10000000000000001</length>
            <radius>0.01</radius>
          </cylinder>
        </geometry>
        <material>
          <script>
            <name>Gazebo/Black</name>
            <uri>file://media/materials/scripts/gazebo.material</uri>
          </script>
          <diffuse>0 0 0 0.5</diffuse>
          <ambient>0 0 0 0.5</ambient>
        </material>
      </visual>
      <visual name='base_footprint_fixed_joint_lump__laser_link_visual_6'>
        <pose>0 0 0.24099999999999999 0 0 0</pose>
        <geometry>
          <cylinder>
            <length>0.02</length>
            <radius>0.02</radius>
          </cylinder>
        </geometry>
        <material>
          <script>
            <name>Gazebo/Black</name>
            <uri>file://media/materials/scripts/gazebo.material</uri>
          </script>
          <diffuse>0 0 0 0.5</diffuse>
          <ambient>0 0 0 0.5</ambient>
        </material>
      </visual>
      <sensor name='laser_sensor' type='gpu_lidar'>
        <topic>/scan</topic>
        <always_on>true</always_on>
        <update_rate>10</update_rate>
        <visualize>true</visualize>
        <lidar>
          <scan>
            <horizontal>
              <samples>640</samples>
              <resolution>1</resolution>
              <min_angle>0</min_angle>
              <max_angle>6.2800000000000002</max_angle>
            </horizontal>
            <vertical>
              <samples>1</samples>
              <resolution>0.01</resolution>
              <min_angle>0</min_angle>
              <max_angle>0</max_angle>
            </vertical>
          </scan>
          <range>
            <min>0.080000000000000002</min>
            <max>10</max>
            <resolution>0.01</resolution>
          </range>
        </lidar>
        <pose>0 0 0.24099999999999999 0 0 0</pose>
      </sensor>
    </link>
    <joint name='left_wheel_joint' type='revolute'>
      <pose relative_to='base_footprint'>0 0.10000000000000001 0.031 0 0 0</pose>
      <parent>base_footprint</parent>
      <child>left_wheel_link</child>
      <axis>
        <xyz>0 1 0</xyz>
        <limit>
          <lower>-inf</lower>
          <upper>inf</upper>
        </limit>
        <dynamics>
          <spring_reference>0</spring_reference>
          <spring_stiffness>0</spring_stiffness>
        </dynamics>
      </axis>
    </joint>
    <link name='left_wheel_link'>
      <pose relative_to='left_wheel_joint'>0 0 0 0 0 0</pose>
      <inertial>
        <pose>0 0 0 0 0 0</pose>
        <mass>0.050000000000000003</mass>
        <inertia>
          <ixx>1.9466666666666671e-05</ixx>
          <ixy>0</ixy>
          <ixz>0</ixz>
          <iyy>1.9466666666666671e-05</iyy>
          <iyz>0</iyz>
          <izz>2.5599999999999999e-05</izz>
        </inertia>
      </inertial>
      <collision name='left_wheel_link_collision'>
        <pose>0 0 0 1.5707899999999999 0 0</pose>
        <geometry>
          <cylinder>
            <length>0.040000000000000001</length>
            <radius>0.032000000000000001</radius>
          </cylinder>
        </geometry>
        <surface>
          <contact>
            <ode>
              <kp>1000000000</kp>
              <kd>1</kd>
            </ode>
          </contact>
          <friction>
            <ode>
              <mu>20</mu>
              <mu2>20</mu2>
            </ode>
          </friction>
        </surface>
      </collision>
      <visual name='left_wheel_link_visual'>
        <pose>0 0 0 1.5707899999999999 0 0</pose>
        <geometry>
          <cylinder>
            <length>0.040000000000000001</length>
            <radius>0.032000000000000001</radius>
          </cylinder>
        </geometry>
        <material>
          <diffuse>1 0 0 0.800000012</diffuse>
          <ambient>1 0 0 0.800000012</ambient>
        </material>
      </visual>
    </link>
    <joint name='right_wheel_joint' type='revolute'>
      <pose relative_to='base_footprint'>0 -0.10000000000000001 0.031 0 0 0</pose>
      <parent>base_footprint</parent>
      <child>right_wheel_link</child>
      <axis>
        <xyz>0 1 0</xyz>
        <limit>
          <lower>-inf</lower>
          <upper>inf</upper>
        </limit>
        <dynamics>
          <spring_reference>0</spring_reference>
          <spring_stiffness>0</spring_stiffness>
        </dynamics>
      </axis>
    </joint>
    <link name='right_wheel_link'>
      <pose relative_to='right_wheel_joint'>0 0 0 0 0 0</pose>
      <inertial>
        <pose>0 0 0 0 0 0</pose>
        <mass>0.050000000000000003</mass>
        <inertia>
          <ixx>1.9466666666666671e-05</ixx>
          <ixy>0</ixy>
          <ixz>0</ixz>
          <iyy>1.9466666666666671e-05</iyy>
          <iyz>0</iyz>
          <izz>2.5599999999999999e-05</izz>
        </inertia>
      </inertial>
      <collision name='right_wheel_link_collision'>
        <pose>0 0 0 1.5707899999999999 0 0</pose>
        <geometry>
          <cylinder>
            <length>0.040000000000000001</length>
            <radius>0.032000000000000001</radius>
          </cylinder>
        </geometry>
        <surface>
          <contact>
            <ode>
              <kp>1000000000</kp>
              <kd>1</kd>
            </ode>
          </contact>
          <friction>
            <ode>
              <mu>20</mu>
              <mu2>20</mu2>
            </ode>
          </friction>
        </surface>
      </collision>
      <visual name='right_wheel_link_visual'>
        <pose>0 0 0 1.5707899999999999 0 0</pose>
        <geometry>
          <cylinder>
            <length>0.040000000000000001</length>
            <radius>0.032000000000000001</radius>
          </cylinder>
        </geometry>
        <material>
          <diffuse>1 0 0 0.800000012</diffuse>
          <ambient>1 0 0 0.800000012</ambient>
        </material>
      </visual>
    </link>
    <plugin name='gz_ros2_control::GazeboSimROS2ControlPlugin' filename='libgz_ros2_control-system.so'>
      <parameters>/home/nenlian/checkout/robot_private/colcon_ws/install/robot_description/share/robot_description/config/robot_ros2_controller.yaml</parameters>
    </plugin>
    <frame name='back_caster_joint' attached_to='base_link'>
      <pose>-0.080000000000000002 0 -0.075999999999999998 0 0 0</pose>
    </frame>
    <frame name='back_caster_link' attached_to='back_caster_joint'>
      <pose>0 0 0 0 0 0</pose>
    </frame>
    <frame name='camera_joint' attached_to='base_link'>
      <pose>0.10000000000000001 0 0.080000000000000002 0 0 0</pose>
    </frame>
    <frame name='camera_link' attached_to='camera_joint'>
      <pose>0 0 0 0 0 0</pose>
    </frame>
    <frame name='front_caster_joint' attached_to='base_link'>
      <pose>0.080000000000000002 0 -0.075999999999999998 0 0 0</pose>
    </frame>
    <frame name='front_caster_link' attached_to='front_caster_joint'>
      <pose>0 0 0 0 0 0</pose>
    </frame>
    <frame name='imu_joint' attached_to='base_link'>
      <pose>0 0 0.02 0 0 0</pose>
    </frame>
    <frame name='imu_link' attached_to='imu_joint'>
      <pose>0 0 0 0 0 0</pose>
    </frame>
    <frame name='laser_joint' attached_to='laser_cylinder_link'>
      <pose>0 0 0.050000000000000003 0 0 0</pose>
    </frame>
    <frame name='laser_link' attached_to='laser_joint'>
      <pose>0 0 0 0 0 0</pose>
    </frame>
    <frame name='laser_cylinder_joint' attached_to='base_link'>
      <pose>0 0 0.10000000000000001 0 0 0</pose>
    </frame>
    <frame name='laser_cylinder_link' attached_to='laser_cylinder_joint'>
      <pose>0 0 0 0 0 0</pose>
    </frame>
    <frame name='joint_name' attached_to='base_footprint'>
      <pose>0 0 0.090999999999999998 0 0 0</pose>
    </frame>
    <frame name='base_link' attached_to='joint_name'>
      <pose>0 0 0 0 0 0</pose>
    </frame>
  </model>
</sdf>
