<?xml version="1.0" ?>
<!-- =================================================================================== -->
<!-- |    This document was autogenerated by xacro from robot.urdf.xacro               | -->
<!-- |    EDITING THIS FILE BY HAND IS NOT RECOMMENDED                                 | -->
<!-- =================================================================================== -->
<robot name="robot_presatation">
  <!-- ==============================
       2. 调用宏，生成机器人结构
  =============================== -->
  <link name="base_footprint">

        </link>
  <!--körper-->
  <link name="base_link">
    <!--Beschreibung-->
    <visual>
      <origin rpy="0.0 0.0 0.0" xyz="0.0 0.0 0.0"/>
      <!--Form-->
      <geometry>
        <cylinder length="0.12" radius="0.1"/>
      </geometry>
      <material name="white">
        <color rgba="1.0 1.0 1.0 0.5"/>
      </material>
    </visual>
    <collision>
      <origin rpy="0.0 0.0 0.0" xyz="0.0 0.0 0.0"/>
      <!--Form-->
      <geometry>
        <cylinder length="0.12" radius="0.1"/>
      </geometry>
      <material name="white">
        <color rgba="1.0 1.0 1.0 0.5"/>
      </material>
    </collision>
    <inertial>
      <mass value="1.0"/>
      <inertia ixx="0.0037000000000000006" ixy="0.0" ixz="0.0" iyy="0.0037000000000000006" iyz="0.0" izz="0.005000000000000001"/>
    </inertial>
  </link>
  <joint name="joint_name" type="fixed">
    <origin rpy="0.0 0.0 0.0" xyz="0.0 0.0 0.091"/>
    <parent link="base_footprint"/>
    <child link="base_link"/>
  </joint>
  <!-- IMU 支撑底座 -->
  <link name="imu_link">
    <visual>
      <origin rpy="0 0 0" xyz="0 0 0"/>
      <geometry>
        <box size="0.02 0.02 0.02"/>
      </geometry>
      <material name="grey">
        <color rgba="0.3 0.3 0.3 1.0"/>
      </material>
    </visual>
    <collision>
      <origin rpy="0 0 0" xyz="0 0 0"/>
      <geometry>
        <box size="0.02 0.02 0.02"/>
      </geometry>
    </collision>
    <inertial>
      <mass value="0.02"/>
      <inertia ixx="1.3333333333333334e-06" ixy="0.0" ixz="0.0" iyy="1.3333333333333334e-06" iyz="0.0" izz="1.3333333333333334e-06"/>
    </inertial>
    <!-- ✅ Gazebo Harmonic 格式的 IMU 传感器 -->
    <sensor name="imu_sensor" type="imu">
      <topic>imu</topic>
      <pose>0 0 0 0 0 0</pose>
      <always_on>true</always_on>
      <update_rate>100</update_rate>
      <visualize>true</visualize>
    </sensor>
  </link>
  <!-- 固定关节 -->
  <joint name="imu_joint" type="fixed">
    <origin rpy="0 0 0" xyz="0.0 0.0 0.02"/>
    <parent link="base_link"/>
    <child link="imu_link"/>
  </joint>
  <!-- Gazebo 材质 -->
  <gazebo reference="imu_link">
    <material>Gazebo/Grey</material>
  </gazebo>
  <!-- 摄像头外壳 -->
  <link name="camera_link">
    <visual>
      <origin rpy="0.0 0.0 0.0" xyz="0.0 0.0 0.0"/>
      <geometry>
        <box size="0.02 0.10 0.02"/>
      </geometry>
      <material name="black">
        <color rgba="0.0 0.0 0.0 0.5"/>
      </material>
    </visual>
    <collision>
      <origin rpy="0.0 0.0 0.0" xyz="0.0 0.0 0.0"/>
      <geometry>
        <box size="0.02 0.10 0.02"/>
      </geometry>
    </collision>
    <inertial>
      <mass value="0.1"/>
      <inertia ixx="8.666666666666668e-05" ixy="0.0" ixz="0.0" iyy="6.666666666666667e-06" iyz="0.0" izz="8.666666666666668e-05"/>
    </inertial>
    <!-- ✅ Gazebo Harmonic 兼容摄像头传感器定义 -->
    <sensor name="camera_sensor" type="camera">
      <topic>camera/image</topic>
      <pose>0 0 0.05 0 0 0</pose>
      <always_on>true</always_on>
      <update_rate>30</update_rate>
      <visualize>true</visualize>
      <camera>
        <horizontal_fov>1.047</horizontal_fov>
        <image>
          <width>1280</width>
          <height>720</height>
          <format>R8G8B8</format>
        </image>
        <clip>
          <near>0.05</near>
          <far>50.0</far>
        </clip>
      </camera>
    </sensor>
  </link>
  <!-- 固定关节 -->
  <joint name="camera_joint" type="fixed">
    <origin rpy="0.0 0.0 0.0" xyz="0.10 0.0 0.08"/>
    <parent link="base_link"/>
    <child link="camera_link"/>
  </joint>
  <!-- 材质 -->
  <gazebo reference="camera_link">
    <material>Gazebo/Black</material>
  </gazebo>
  <!-- 激光雷达支撑杆 -->
  <link name="laser_cylinder_link">
    <visual>
      <origin rpy="0.0 0.0 0.0" xyz="0.0 0.0 0.0"/>
      <geometry>
        <cylinder length="0.10" radius="0.01"/>
      </geometry>
      <material name="black">
        <color rgba="0.0 0.0 0.0 1.0"/>
      </material>
    </visual>
    <collision>
      <origin rpy="0.0 0.0 0.0" xyz="0.0 0.0 0.0"/>
      <geometry>
        <cylinder length="0.10" radius="0.01"/>
      </geometry>
    </collision>
    <inertial>
      <mass value="0.05"/>
      <inertia ixx="4.2916666666666675e-05" ixy="0.0" ixz="0.0" iyy="4.2916666666666675e-05" iyz="0.0" izz="2.5e-06"/>
    </inertial>
  </link>
  <!-- 激光雷达主体 -->
  <link name="laser_link">
    <visual>
      <origin rpy="0.0 0.0 0.0" xyz="0.0 0.0 0.0"/>
      <geometry>
        <cylinder length="0.02" radius="0.02"/>
      </geometry>
      <material name="black">
        <color rgba="0.0 0.0 0.0 1.0"/>
      </material>
    </visual>
    <collision>
      <origin rpy="0.0 0.0 0.0" xyz="0.0 0.0 0.0"/>
      <geometry>
        <cylinder length="0.02" radius="0.02"/>
      </geometry>
    </collision>
    <inertial>
      <mass value="0.1"/>
      <inertia ixx="1.3333333333333332e-05" ixy="0.0" ixz="0.0" iyy="1.3333333333333332e-05" iyz="0.0" izz="2e-05"/>
    </inertial>
  </link>
  <!-- joints -->
  <joint name="laser_joint" type="fixed">
    <origin rpy="0.0 0.0 0.0" xyz="0.0 0.0 0.05"/>
    <parent link="laser_cylinder_link"/>
    <child link="laser_link"/>
  </joint>
  <joint name="laser_cylinder_joint" type="fixed">
    <origin rpy="0.0 0.0 0.0" xyz="0.0 0.0 0.10"/>
    <parent link="base_link"/>
    <child link="laser_cylinder_link"/>
  </joint>
  <!-- 材质 -->
  <gazebo reference="laser_cylinder_link">
    <material>Gazebo/Black</material>
  </gazebo>
  <gazebo reference="laser_link">
    <material>Gazebo/Black</material>
  </gazebo>
  <!-- ✅ 修正版 Lidar 传感器绑定 -->
  <gazebo reference="laser_link">
    <sensor name="laser_sensor" type="gpu_lidar">
      <topic>/scan</topic>
      <always_on>true</always_on>
      <update_rate>10</update_rate>
      <visualize>true</visualize>
      <pose>0 0 0 0 0 0</pose>
      <lidar>
        <scan>
          <horizontal>
            <samples>640</samples>
            <resolution>1</resolution>
            <min_angle>0</min_angle>
            <max_angle>6.28</max_angle>
          </horizontal>
          <vertical>
            <samples>1</samples>
            <resolution>0.01</resolution>
            <min_angle>0</min_angle>
            <max_angle>0</max_angle>
          </vertical>
        </scan>
        <range>
          <min>0.08</min>
          <max>10.0</max>
          <resolution>0.01</resolution>
        </range>
      </lidar>
    </sensor>
  </gazebo>
  <link name="left_wheel_link">
    <!--Beschreibung-->
    <visual>
      <origin rpy="1.57079 0.0 0.0" xyz="0.0 0.0 0.0"/>
      <!--Form-->
      <geometry>
        <cylinder length="0.04" radius="0.032"/>
      </geometry>
      <material name="red">
        <color rgba="1.0 0.0 0.0 0.8"/>
      </material>
    </visual>
    <collision>
      <origin rpy="1.57079 0.0 0.0" xyz="0.0 0.0 0.0"/>
      <!--Form-->
      <geometry>
        <cylinder length="0.04" radius="0.032"/>
      </geometry>
      <material name="red">
        <color rgba="1.0 0.0 0.0 0.8"/>
      </material>
    </collision>
    <inertial>
      <mass value="0.05"/>
      <inertia ixx="1.9466666666666668e-05" ixy="0.0" ixz="0.0" iyy="1.9466666666666668e-05" iyz="0.0" izz="2.5600000000000002e-05"/>
    </inertial>
  </link>
  <joint name="left_wheel_joint" type="continuous">
    <origin rpy="0.0 0.0 0.0" xyz="0.0  0.10 -0.06"/>
    <parent link="base_link"/>
    <child link="left_wheel_link"/>
    <axis xyz="0.0 1.0 0.0"/>
  </joint>
  <gazebo reference="left_wheel_link">
    <mu1 value="20.0"/>
    <mu2 value="20.0"/>
    <kp value="1000000000.0"/>
    <kd value="1.0"/>
  </gazebo>
  <link name="right_wheel_link">
    <!--Beschreibung-->
    <visual>
      <origin rpy="1.57079 0.0 0.0" xyz="0.0 0.0 0.0"/>
      <!--Form-->
      <geometry>
        <cylinder length="0.04" radius="0.032"/>
      </geometry>
      <material name="red">
        <color rgba="1.0 0.0 0.0 0.8"/>
      </material>
    </visual>
    <collision>
      <origin rpy="1.57079 0.0 0.0" xyz="0.0 0.0 0.0"/>
      <!--Form-->
      <geometry>
        <cylinder length="0.04" radius="0.032"/>
      </geometry>
      <material name="red">
        <color rgba="1.0 0.0 0.0 0.8"/>
      </material>
    </collision>
    <inertial>
      <mass value="0.05"/>
      <inertia ixx="1.9466666666666668e-05" ixy="0.0" ixz="0.0" iyy="1.9466666666666668e-05" iyz="0.0" izz="2.5600000000000002e-05"/>
    </inertial>
  </link>
  <joint name="right_wheel_joint" type="continuous">
    <origin rpy="0.0 0.0 0.0" xyz="0.0 -0.10 -0.06"/>
    <parent link="base_link"/>
    <child link="right_wheel_link"/>
    <axis xyz="0.0 1.0 0.0"/>
  </joint>
  <gazebo reference="right_wheel_link">
    <mu1 value="20.0"/>
    <mu2 value="20.0"/>
    <kp value="1000000000.0"/>
    <kd value="1.0"/>
  </gazebo>
  <link name="front_caster_link">
    <!--Beschreibung-->
    <visual>
      <origin rpy="0 0.0 0.0" xyz="0.0 0.0 0.0"/>
      <!--Form-->
      <geometry>
        <sphere radius="0.016"/>
      </geometry>
      <material name="red">
        <color rgba="1.0 0.0 0.0 0.8"/>
      </material>
    </visual>
    <collision>
      <origin rpy="0 0.0 0.0" xyz="0.0 0.0 0.0"/>
      <!--Form-->
      <geometry>
        <sphere radius="0.016"/>
      </geometry>
      <material name="red">
        <color rgba="1.0 0.0 0.0 0.8"/>
      </material>
    </collision>
    <inertial>
      <mass value="0.05"/>
      <inertia ixx="5.120000000000001e-06" ixy="0.0" ixz="0.0" iyy="5.120000000000001e-06" iyz="0.0" izz="5.120000000000001e-06"/>
    </inertial>
  </link>
  <joint name="front_caster_joint" type="fixed">
    <origin rpy="0.0 0.0 0.0" xyz="0.08  0.0 -0.076"/>
    <parent link="base_link"/>
    <child link="front_caster_link"/>
  </joint>
  <gazebo reference="front_caster_link">
    <mu1 value="0.0"/>
    <mu2 value="0.0"/>
    <kp value="1000000000.0"/>
    <kd value="1.0"/>
  </gazebo>
  <link name="back_caster_link">
    <!--Beschreibung-->
    <visual>
      <origin rpy="0 0.0 0.0" xyz="0.0 0.0 0.0"/>
      <!--Form-->
      <geometry>
        <sphere radius="0.016"/>
      </geometry>
      <material name="red">
        <color rgba="1.0 0.0 0.0 0.8"/>
      </material>
    </visual>
    <collision>
      <origin rpy="0 0.0 0.0" xyz="0.0 0.0 0.0"/>
      <!--Form-->
      <geometry>
        <sphere radius="0.016"/>
      </geometry>
      <material name="red">
        <color rgba="1.0 0.0 0.0 0.8"/>
      </material>
    </collision>
    <inertial>
      <mass value="0.05"/>
      <inertia ixx="5.120000000000001e-06" ixy="0.0" ixz="0.0" iyy="5.120000000000001e-06" iyz="0.0" izz="5.120000000000001e-06"/>
    </inertial>
  </link>
  <joint name="back_caster_joint" type="fixed">
    <origin rpy="0.0 0.0 0.0" xyz="-0.08 0.0 -0.076"/>
    <parent link="base_link"/>
    <child link="back_caster_link"/>
  </joint>
  <gazebo reference="back_caster_link">
    <mu1 value="0.0"/>
    <mu2 value="0.0"/>
    <kp value="1000000000.0"/>
    <kd value="1.0"/>
  </gazebo>
  <ros2_control name="robot_ros2_control" type="system">
    <hardware>
      <plugin>gz_ros2_control/GazeboSimSystem</plugin>
    </hardware>
    <joint name="left_wheel_joint" type="revolute">
      <command_interface name="velocity">
        <param name="min">-1</param>
        <param name="max">1</param>
      </command_interface>
      <command_interface name="effort">
        <param name="min">-0.1</param>
        <param name="max">0.1</param>
      </command_interface>
      <command_interface name="position"/>
      <state_interface name="velocity"/>
      <state_interface name="effort"/>
    </joint>
    <joint name="right_wheel_joint" type="revolute">
      <command_interface name="velocity">
        <param name="min">-1</param>
        <param name="max">1</param>
      </command_interface>
      <command_interface name="effort">
        <param name="min">-0.1</param>
        <param name="max">0.1</param>
      </command_interface>
      <command_interface name="position"/>
      <state_interface name="velocity"/>
      <state_interface name="effort"/>
      l
     
    </joint>
  </ros2_control>
  <gazebo>
    <plugin filename="libgz_ros2_control-system.so" name="gz_ros2_control::GazeboSimROS2ControlPlugin">
      <parameters>
        /home/nenlian/checkout/robot_private/colcon_ws/install/robot_description/share/robot_description/config/robot_ros2_controller.yaml
      </parameters>
    </plugin>
  </gazebo>
</robot>
